[2025-10-29T14:42:03.517+0000] {taskinstance.py:1956} INFO - Dependencies all met for dep_context=non-requeueable deps ti=<TaskInstance: dag2_kafka_elastic_gcs.PutElasticSearch scheduled__2025-10-29T14:41:00+00:00 [queued]>
[2025-10-29T14:42:03.526+0000] {taskinstance.py:1956} INFO - Dependencies all met for dep_context=requeueable deps ti=<TaskInstance: dag2_kafka_elastic_gcs.PutElasticSearch scheduled__2025-10-29T14:41:00+00:00 [queued]>
[2025-10-29T14:42:03.527+0000] {taskinstance.py:2170} INFO - Starting attempt 1 of 1
[2025-10-29T14:42:03.540+0000] {taskinstance.py:2191} INFO - Executing <Task(_PythonDecoratedOperator): PutElasticSearch> on 2025-10-29 14:41:00+00:00
[2025-10-29T14:42:03.551+0000] {standard_task_runner.py:60} INFO - Started process 836 to run task
[2025-10-29T14:42:03.555+0000] {standard_task_runner.py:87} INFO - Running: ['***', 'tasks', 'run', 'dag2_kafka_elastic_gcs', 'PutElasticSearch', 'scheduled__2025-10-29T14:41:00+00:00', '--job-id', '411', '--raw', '--subdir', 'DAGS_FOLDER/dag2_elastic_gcs_ingestion.py', '--cfg-path', '/tmp/tmp2n0mbxos']
[2025-10-29T14:42:03.558+0000] {standard_task_runner.py:88} INFO - Job 411: Subtask PutElasticSearch
[2025-10-29T14:42:03.624+0000] {task_command.py:423} INFO - Running <TaskInstance: dag2_kafka_elastic_gcs.PutElasticSearch scheduled__2025-10-29T14:41:00+00:00 [running]> on host c91e5c2c38a7
[2025-10-29T14:42:03.746+0000] {taskinstance.py:2480} INFO - Exporting env vars: AIRFLOW_CTX_DAG_OWNER='***' AIRFLOW_CTX_DAG_ID='dag2_kafka_elastic_gcs' AIRFLOW_CTX_TASK_ID='PutElasticSearch' AIRFLOW_CTX_EXECUTION_DATE='2025-10-29T14:41:00+00:00' AIRFLOW_CTX_TRY_NUMBER='1' AIRFLOW_CTX_DAG_RUN_ID='scheduled__2025-10-29T14:41:00+00:00'
[2025-10-29T14:42:03.755+0000] {logging_mixin.py:188} WARNING - /home/***/.local/lib/python3.8/site-packages/***/operators/python.py:216 AirflowProviderDeprecationWarning: This class is deprecated.
            Please use `***.providers.elasticsearch.hooks.elasticsearch.ElasticsearchSQLHook`.
[2025-10-29T14:42:03.770+0000] {base.py:83} INFO - Using connection ID 'elasticsearch_default' for task execution.
[2025-10-29T14:42:03.776+0000] {_transport.py:358} INFO - HEAD http://localhost:9200/taxi_rides [status:N/A duration:0.002s]
[2025-10-29T14:42:03.776+0000] {_node_pool.py:249} WARNING - Node <Urllib3HttpNode(http://localhost:9200)> has failed for 1 times in a row, putting on 1 second timeout
[2025-10-29T14:42:03.777+0000] {_transport.py:395} WARNING - Retrying request after failure (attempt 0 of 3)
Traceback (most recent call last):
  File "/home/airflow/.local/lib/python3.8/site-packages/elastic_transport/_transport.py", line 328, in perform_request
    meta, raw_data = node.perform_request(
  File "/home/airflow/.local/lib/python3.8/site-packages/elastic_transport/_node/_http_urllib3.py", line 202, in perform_request
    raise err from None
elastic_transport.ConnectionError: Connection error caused by: NewConnectionError(<urllib3.connection.HTTPConnection object at 0x7d72bbbffbb0>: Failed to establish a new connection: [Errno 111] Connection refused)
[2025-10-29T14:42:03.779+0000] {_transport.py:358} INFO - HEAD http://localhost:9200/taxi_rides [status:N/A duration:0.000s]
[2025-10-29T14:42:03.780+0000] {_node_pool.py:249} WARNING - Node <Urllib3HttpNode(http://localhost:9200)> has failed for 2 times in a row, putting on 2 second timeout
[2025-10-29T14:42:03.780+0000] {_transport.py:395} WARNING - Retrying request after failure (attempt 1 of 3)
Traceback (most recent call last):
  File "/home/airflow/.local/lib/python3.8/site-packages/elastic_transport/_transport.py", line 328, in perform_request
    meta, raw_data = node.perform_request(
  File "/home/airflow/.local/lib/python3.8/site-packages/elastic_transport/_node/_http_urllib3.py", line 202, in perform_request
    raise err from None
elastic_transport.ConnectionError: Connection error caused by: NewConnectionError(<urllib3.connection.HTTPConnection object at 0x7d72bbbffd60>: Failed to establish a new connection: [Errno 111] Connection refused)
[2025-10-29T14:42:03.781+0000] {_transport.py:358} INFO - HEAD http://localhost:9200/taxi_rides [status:N/A duration:0.001s]
[2025-10-29T14:42:03.782+0000] {_node_pool.py:249} WARNING - Node <Urllib3HttpNode(http://localhost:9200)> has failed for 3 times in a row, putting on 4 second timeout
[2025-10-29T14:42:03.782+0000] {_transport.py:395} WARNING - Retrying request after failure (attempt 2 of 3)
Traceback (most recent call last):
  File "/home/airflow/.local/lib/python3.8/site-packages/elastic_transport/_transport.py", line 328, in perform_request
    meta, raw_data = node.perform_request(
  File "/home/airflow/.local/lib/python3.8/site-packages/elastic_transport/_node/_http_urllib3.py", line 202, in perform_request
    raise err from None
elastic_transport.ConnectionError: Connection error caused by: NewConnectionError(<urllib3.connection.HTTPConnection object at 0x7d72bbb900d0>: Failed to establish a new connection: [Errno 111] Connection refused)
[2025-10-29T14:42:03.783+0000] {_transport.py:358} INFO - HEAD http://localhost:9200/taxi_rides [status:N/A duration:0.001s]
[2025-10-29T14:42:03.784+0000] {_node_pool.py:249} WARNING - Node <Urllib3HttpNode(http://localhost:9200)> has failed for 4 times in a row, putting on 8 second timeout
[2025-10-29T14:42:03.784+0000] {dag2_elastic_gcs_ingestion.py:120} ERROR - ❌ Erreur d’insertion Elasticsearch : Connection error caused by: ConnectionError(Connection error caused by: NewConnectionError(<urllib3.connection.HTTPConnection object at 0x7d72bbbffbb0>: Failed to establish a new connection: [Errno 111] Connection refused))
[2025-10-29T14:42:03.785+0000] {python.py:201} INFO - Done. Returned value was: None
[2025-10-29T14:42:03.796+0000] {taskinstance.py:1138} INFO - Marking task as SUCCESS. dag_id=dag2_kafka_elastic_gcs, task_id=PutElasticSearch, execution_date=20251029T144100, start_date=20251029T144203, end_date=20251029T144203
[2025-10-29T14:42:03.848+0000] {local_task_job_runner.py:234} INFO - Task exited with return code 0
[2025-10-29T14:42:03.870+0000] {taskinstance.py:3280} INFO - 0 downstream tasks scheduled from follow-on schedule check
