[2025-10-29T20:05:02.132+0000] {scheduler_job_runner.py:781} ERROR - Executor reports task instance <TaskInstance: dag1_calcul_trajet_kafka.ConsumKafka scheduled__2025-10-29T20:04:00+00:00 [queued]> finished (failed) although the task says it's queued. (Info: None) Was the task killed externally?
