[2025-10-29T15:32:25.053+0000] {taskinstance.py:1956} INFO - Dependencies all met for dep_context=non-requeueable deps ti=<TaskInstance: dag2_kafka_elastic_gcs.ConsumeKafka manual__2025-10-29T15:32:13.377161+00:00 [queued]>
[2025-10-29T15:32:25.073+0000] {taskinstance.py:1956} INFO - Dependencies all met for dep_context=requeueable deps ti=<TaskInstance: dag2_kafka_elastic_gcs.ConsumeKafka manual__2025-10-29T15:32:13.377161+00:00 [queued]>
[2025-10-29T15:32:25.075+0000] {taskinstance.py:2170} INFO - Starting attempt 1 of 1
[2025-10-29T15:32:25.129+0000] {taskinstance.py:2191} INFO - Executing <Task(_PythonDecoratedOperator): ConsumeKafka> on 2025-10-29 15:32:13.377161+00:00
[2025-10-29T15:32:25.170+0000] {standard_task_runner.py:60} INFO - Started process 76 to run task
[2025-10-29T15:32:25.192+0000] {standard_task_runner.py:87} INFO - Running: ['***', 'tasks', 'run', 'dag2_kafka_elastic_gcs', 'ConsumeKafka', 'manual__2025-10-29T15:32:13.377161+00:00', '--job-id', '13', '--raw', '--subdir', 'DAGS_FOLDER/dag2_elastic_gcs_ingestion.py', '--cfg-path', '/tmp/tmp41o5lzni']
[2025-10-29T15:32:25.204+0000] {standard_task_runner.py:88} INFO - Job 13: Subtask ConsumeKafka
[2025-10-29T15:32:42.408+0000] {cli_action_loggers.py:135} WARNING - Failed to log action (psycopg2.OperationalError) could not translate host name "postgres" to address: Temporary failure in name resolution

(Background on this error at: https://sqlalche.me/e/14/e3q8)
[2025-10-29T15:32:42.511+0000] {job.py:213} ERROR - Job heartbeat got an exception
Traceback (most recent call last):
  File "/home/airflow/.local/lib/python3.8/site-packages/sqlalchemy/engine/base.py", line 3371, in _wrap_pool_connect
    return fn()
  File "/home/airflow/.local/lib/python3.8/site-packages/sqlalchemy/pool/base.py", line 327, in connect
    return _ConnectionFairy._checkout(self)
  File "/home/airflow/.local/lib/python3.8/site-packages/sqlalchemy/pool/base.py", line 894, in _checkout
    fairy = _ConnectionRecord.checkout(pool)
  File "/home/airflow/.local/lib/python3.8/site-packages/sqlalchemy/pool/base.py", line 493, in checkout
    rec = pool._do_get()
  File "/home/airflow/.local/lib/python3.8/site-packages/sqlalchemy/pool/impl.py", line 256, in _do_get
    return self._create_connection()
  File "/home/airflow/.local/lib/python3.8/site-packages/sqlalchemy/pool/base.py", line 273, in _create_connection
    return _ConnectionRecord(self)
  File "/home/airflow/.local/lib/python3.8/site-packages/sqlalchemy/pool/base.py", line 388, in __init__
    self.__connect()
  File "/home/airflow/.local/lib/python3.8/site-packages/sqlalchemy/pool/base.py", line 691, in __connect
    pool.logger.debug("Error on connect(): %s", e)
  File "/home/airflow/.local/lib/python3.8/site-packages/sqlalchemy/util/langhelpers.py", line 70, in __exit__
    compat.raise_(
  File "/home/airflow/.local/lib/python3.8/site-packages/sqlalchemy/util/compat.py", line 211, in raise_
    raise exception
  File "/home/airflow/.local/lib/python3.8/site-packages/sqlalchemy/pool/base.py", line 686, in __connect
    self.dbapi_connection = connection = pool._invoke_creator(self)
  File "/home/airflow/.local/lib/python3.8/site-packages/sqlalchemy/engine/create.py", line 574, in connect
    return dialect.connect(*cargs, **cparams)
  File "/home/airflow/.local/lib/python3.8/site-packages/sqlalchemy/engine/default.py", line 598, in connect
    return self.dbapi.connect(*cargs, **cparams)
  File "/home/airflow/.local/lib/python3.8/site-packages/psycopg2/__init__.py", line 122, in connect
    conn = _connect(dsn, connection_factory=connection_factory, **kwasync)
psycopg2.OperationalError: could not translate host name "postgres" to address: Temporary failure in name resolution


The above exception was the direct cause of the following exception:

Traceback (most recent call last):
  File "/home/airflow/.local/lib/python3.8/site-packages/airflow/jobs/job.py", line 187, in heartbeat
    self._merge_from(Job._fetch_from_db(self, session))
  File "/home/airflow/.local/lib/python3.8/site-packages/airflow/api_internal/internal_api_call.py", line 114, in wrapper
    return func(*args, **kwargs)
  File "/home/airflow/.local/lib/python3.8/site-packages/airflow/utils/session.py", line 76, in wrapper
    return func(*args, **kwargs)
  File "/home/airflow/.local/lib/python3.8/site-packages/airflow/jobs/job.py", line 308, in _fetch_from_db
    session.merge(job)
  File "/home/airflow/.local/lib/python3.8/site-packages/sqlalchemy/orm/session.py", line 3056, in merge
    return self._merge(
  File "/home/airflow/.local/lib/python3.8/site-packages/sqlalchemy/orm/session.py", line 3136, in _merge
    merged = self.get(
  File "/home/airflow/.local/lib/python3.8/site-packages/sqlalchemy/orm/session.py", line 2853, in get
    return self._get_impl(
  File "/home/airflow/.local/lib/python3.8/site-packages/sqlalchemy/orm/session.py", line 2975, in _get_impl
    return db_load_fn(
  File "/home/airflow/.local/lib/python3.8/site-packages/sqlalchemy/orm/loading.py", line 530, in load_on_pk_identity
    session.execute(
  File "/home/airflow/.local/lib/python3.8/site-packages/sqlalchemy/orm/session.py", line 1716, in execute
    conn = self._connection_for_bind(bind)
  File "/home/airflow/.local/lib/python3.8/site-packages/sqlalchemy/orm/session.py", line 1555, in _connection_for_bind
    return self._transaction._connection_for_bind(
  File "/home/airflow/.local/lib/python3.8/site-packages/sqlalchemy/orm/session.py", line 750, in _connection_for_bind
    conn = bind.connect()
  File "/home/airflow/.local/lib/python3.8/site-packages/sqlalchemy/future/engine.py", line 412, in connect
    return super(Engine, self).connect()
  File "/home/airflow/.local/lib/python3.8/site-packages/sqlalchemy/engine/base.py", line 3325, in connect
    return self._connection_cls(self, close_with_result=close_with_result)
  File "/home/airflow/.local/lib/python3.8/site-packages/sqlalchemy/engine/base.py", line 96, in __init__
    else engine.raw_connection()
  File "/home/airflow/.local/lib/python3.8/site-packages/sqlalchemy/engine/base.py", line 3404, in raw_connection
    return self._wrap_pool_connect(self.pool.connect, _connection)
  File "/home/airflow/.local/lib/python3.8/site-packages/sqlalchemy/engine/base.py", line 3374, in _wrap_pool_connect
    Connection._handle_dbapi_exception_noconnection(
  File "/home/airflow/.local/lib/python3.8/site-packages/sqlalchemy/engine/base.py", line 2208, in _handle_dbapi_exception_noconnection
    util.raise_(
  File "/home/airflow/.local/lib/python3.8/site-packages/sqlalchemy/util/compat.py", line 211, in raise_
    raise exception
  File "/home/airflow/.local/lib/python3.8/site-packages/sqlalchemy/engine/base.py", line 3371, in _wrap_pool_connect
    return fn()
  File "/home/airflow/.local/lib/python3.8/site-packages/sqlalchemy/pool/base.py", line 327, in connect
    return _ConnectionFairy._checkout(self)
  File "/home/airflow/.local/lib/python3.8/site-packages/sqlalchemy/pool/base.py", line 894, in _checkout
    fairy = _ConnectionRecord.checkout(pool)
  File "/home/airflow/.local/lib/python3.8/site-packages/sqlalchemy/pool/base.py", line 493, in checkout
    rec = pool._do_get()
  File "/home/airflow/.local/lib/python3.8/site-packages/sqlalchemy/pool/impl.py", line 256, in _do_get
    return self._create_connection()
  File "/home/airflow/.local/lib/python3.8/site-packages/sqlalchemy/pool/base.py", line 273, in _create_connection
    return _ConnectionRecord(self)
  File "/home/airflow/.local/lib/python3.8/site-packages/sqlalchemy/pool/base.py", line 388, in __init__
    self.__connect()
  File "/home/airflow/.local/lib/python3.8/site-packages/sqlalchemy/pool/base.py", line 691, in __connect
    pool.logger.debug("Error on connect(): %s", e)
  File "/home/airflow/.local/lib/python3.8/site-packages/sqlalchemy/util/langhelpers.py", line 70, in __exit__
    compat.raise_(
  File "/home/airflow/.local/lib/python3.8/site-packages/sqlalchemy/util/compat.py", line 211, in raise_
    raise exception
  File "/home/airflow/.local/lib/python3.8/site-packages/sqlalchemy/pool/base.py", line 686, in __connect
    self.dbapi_connection = connection = pool._invoke_creator(self)
  File "/home/airflow/.local/lib/python3.8/site-packages/sqlalchemy/engine/create.py", line 574, in connect
    return dialect.connect(*cargs, **cparams)
  File "/home/airflow/.local/lib/python3.8/site-packages/sqlalchemy/engine/default.py", line 598, in connect
    return self.dbapi.connect(*cargs, **cparams)
  File "/home/airflow/.local/lib/python3.8/site-packages/psycopg2/__init__.py", line 122, in connect
    conn = _connect(dsn, connection_factory=connection_factory, **kwasync)
sqlalchemy.exc.OperationalError: (psycopg2.OperationalError) could not translate host name "postgres" to address: Temporary failure in name resolution

(Background on this error at: https://sqlalche.me/e/14/e3q8)
[2025-10-29T15:32:42.855+0000] {job.py:221} ERROR - Job heartbeat failed with error. Scheduler is in unhealthy state
[2025-10-29T15:32:43.180+0000] {task_command.py:423} INFO - Running <TaskInstance: dag2_kafka_elastic_gcs.ConsumeKafka manual__2025-10-29T15:32:13.377161+00:00 [running]> on host 46f6cfd4d166
[2025-10-29T15:32:43.546+0000] {taskinstance.py:2480} INFO - Exporting env vars: AIRFLOW_CTX_DAG_OWNER='***' AIRFLOW_CTX_DAG_ID='dag2_kafka_elastic_gcs' AIRFLOW_CTX_TASK_ID='ConsumeKafka' AIRFLOW_CTX_EXECUTION_DATE='2025-10-29T15:32:13.377161+00:00' AIRFLOW_CTX_TRY_NUMBER='1' AIRFLOW_CTX_DAG_RUN_ID='manual__2025-10-29T15:32:13.377161+00:00'
[2025-10-29T15:32:43.549+0000] {dag2_elastic_gcs_ingestion.py:54} INFO - ðŸ“¥ DÃ©marrage de la consommation du topic Kafka 'result'...
[2025-10-29T15:32:43.560+0000] {conn.py:396} INFO - <BrokerConnection client_id=kafka-python-2.2.15, node_id=bootstrap-0 host=kafka:9092 <connecting> [IPv4 ('172.18.0.8', 9092)]>: connecting to kafka:9092 [('172.18.0.8', 9092) IPv4]
[2025-10-29T15:32:43.579+0000] {conn.py:618} INFO - <BrokerConnection client_id=kafka-python-2.2.15, node_id=bootstrap-0 host=kafka:9092 <checking_api_versions_recv> [IPv4 ('172.18.0.8', 9092)]>: Broker version identified as 2.6
[2025-10-29T15:32:43.580+0000] {conn.py:457} INFO - <BrokerConnection client_id=kafka-python-2.2.15, node_id=bootstrap-0 host=kafka:9092 <connected> [IPv4 ('172.18.0.8', 9092)]>: Connection complete.
[2025-10-29T15:32:43.582+0000] {subscription_state.py:181} INFO - Updating subscribed topics to: ('result',)
[2025-10-29T15:32:43.598+0000] {subscription_state.py:254} INFO - Updated partition assignment: [('result', 0)]
[2025-10-29T15:32:43.601+0000] {conn.py:396} INFO - <BrokerConnection client_id=kafka-python-2.2.15, node_id=1 host=kafka:9092 <connecting> [IPv4 ('172.18.0.8', 9092)]>: connecting to kafka:9092 [('172.18.0.8', 9092) IPv4]
[2025-10-29T15:32:43.603+0000] {conn.py:457} INFO - <BrokerConnection client_id=kafka-python-2.2.15, node_id=1 host=kafka:9092 <connected> [IPv4 ('172.18.0.8', 9092)]>: Connection complete.
[2025-10-29T15:32:43.605+0000] {conn.py:945} INFO - <BrokerConnection client_id=kafka-python-2.2.15, node_id=bootstrap-0 host=kafka:9092 <connected> [IPv4 ('172.18.0.8', 9092)]>: Closing connection. 
[2025-10-29T15:32:43.616+0000] {fetcher.py:418} INFO - Resetting offset for partition ('result', 0) to offset 0.
[2025-10-29T15:32:43.629+0000] {conn.py:945} INFO - <BrokerConnection client_id=kafka-python-2.2.15, node_id=1 host=kafka:9092 <connected> [IPv4 ('172.18.0.8', 9092)]>: Closing connection. 
[2025-10-29T15:32:43.630+0000] {dag2_elastic_gcs_ingestion.py:64} INFO - âœ… Message consommÃ© depuis Kafka: {'confort': 'standard', 'prix_base_per_km': 2, 'properties-client': {'logitude': 2.375471605202055, 'latitude': 48.88788877295766, 'nomclient': 'FALL', 'telephoneClient': '060786575'}, 'properties-driver': {'logitude': 3.6905723948788944, 'latitude': 40.41673791351537, 'nomDriver': 'DIOP', 'telephoneDriver': '0760786575'}, 'distance_km': 947.63, 'travel_cost': 1895.27}
[2025-10-29T15:32:43.630+0000] {python.py:201} INFO - Done. Returned value was: {'confort': 'standard', 'prix_base_per_km': 2, 'properties-client': {'logitude': 2.375471605202055, 'latitude': 48.88788877295766, 'nomclient': 'FALL', 'telephoneClient': '060786575'}, 'properties-driver': {'logitude': 3.6905723948788944, 'latitude': 40.41673791351537, 'nomDriver': 'DIOP', 'telephoneDriver': '0760786575'}, 'distance_km': 947.63, 'travel_cost': 1895.27}
[2025-10-29T15:32:43.700+0000] {taskinstance.py:1138} INFO - Marking task as SUCCESS. dag_id=dag2_kafka_elastic_gcs, task_id=ConsumeKafka, execution_date=20251029T153213, start_date=20251029T153225, end_date=20251029T153243
[2025-10-29T15:32:43.777+0000] {local_task_job_runner.py:234} INFO - Task exited with return code 0
[2025-10-29T15:32:43.825+0000] {taskinstance.py:3280} INFO - 1 downstream tasks scheduled from follow-on schedule check
