[2025-10-29T18:32:23.484+0000] {scheduler_job_runner.py:1586} WARNING - Marking task instance <TaskInstance: dag2_kafka_elastic_gcs.ConsumeKafka scheduled__2025-10-29T17:41:00+00:00 [queued]> stuck in queued as failed. If the task instance has available retries, it will be retried.
[2025-10-29T18:32:23.793+0000] {scheduler_job_runner.py:781} ERROR - Executor reports task instance <TaskInstance: dag2_kafka_elastic_gcs.ConsumeKafka scheduled__2025-10-29T17:41:00+00:00 [queued]> finished (failed) although the task says it's queued. (Info: None) Was the task killed externally?
