[2025-10-28T23:26:00.996+0000] {taskinstance.py:1956} INFO - Dependencies all met for dep_context=non-requeueable deps ti=<TaskInstance: dag1_calcul_trajet_kafka.ConsumKafka scheduled__2025-10-28T23:25:00+00:00 [queued]>
[2025-10-28T23:26:01.004+0000] {taskinstance.py:1956} INFO - Dependencies all met for dep_context=requeueable deps ti=<TaskInstance: dag1_calcul_trajet_kafka.ConsumKafka scheduled__2025-10-28T23:25:00+00:00 [queued]>
[2025-10-28T23:26:01.005+0000] {taskinstance.py:2170} INFO - Starting attempt 1 of 1
[2025-10-28T23:26:01.018+0000] {taskinstance.py:2191} INFO - Executing <Task(_PythonDecoratedOperator): ConsumKafka> on 2025-10-28 23:25:00+00:00
[2025-10-28T23:26:01.024+0000] {standard_task_runner.py:60} INFO - Started process 269 to run task
[2025-10-28T23:26:01.027+0000] {standard_task_runner.py:87} INFO - Running: ['***', 'tasks', 'run', 'dag1_calcul_trajet_kafka', 'ConsumKafka', 'scheduled__2025-10-28T23:25:00+00:00', '--job-id', '62', '--raw', '--subdir', 'DAGS_FOLDER/dag1_kafka_processing.py', '--cfg-path', '/tmp/tmpfcsxjzah']
[2025-10-28T23:26:01.029+0000] {standard_task_runner.py:88} INFO - Job 62: Subtask ConsumKafka
[2025-10-28T23:26:01.099+0000] {task_command.py:423} INFO - Running <TaskInstance: dag1_calcul_trajet_kafka.ConsumKafka scheduled__2025-10-28T23:25:00+00:00 [running]> on host eeb62d0a3b5b
[2025-10-28T23:26:01.196+0000] {taskinstance.py:2480} INFO - Exporting env vars: AIRFLOW_CTX_DAG_OWNER='***' AIRFLOW_CTX_DAG_ID='dag1_calcul_trajet_kafka' AIRFLOW_CTX_TASK_ID='ConsumKafka' AIRFLOW_CTX_EXECUTION_DATE='2025-10-28T23:25:00+00:00' AIRFLOW_CTX_TRY_NUMBER='1' AIRFLOW_CTX_DAG_RUN_ID='scheduled__2025-10-28T23:25:00+00:00'
[2025-10-28T23:26:05.195+0000] {conn.py:1516} WARNING - DNS lookup failed for kafka:9092, exception was [Errno -2] Name or service not known. Is your advertised.listeners (called advertised.host.name before Kafka 9) correct and resolvable?
[2025-10-28T23:26:05.196+0000] {conn.py:323} ERROR - <BrokerConnection client_id=kafka-python-2.2.15, node_id=bootstrap-0 host=kafka:9092 <connecting> [unspecified None]>: DNS lookup failed for kafka:9092 (0)
[2025-10-28T23:26:05.197+0000] {conn.py:945} ERROR - <BrokerConnection client_id=kafka-python-2.2.15, node_id=bootstrap-0 host=kafka:9092 <connecting> [unspecified None]>: Closing connection. KafkaConnectionError: DNS failure
[2025-10-28T23:26:05.198+0000] {taskinstance.py:2698} ERROR - Task failed with exception
Traceback (most recent call last):
  File "/home/airflow/.local/lib/python3.8/site-packages/airflow/models/taskinstance.py", line 433, in _execute_task
    result = execute_callable(context=context, **execute_callable_kwargs)
  File "/home/airflow/.local/lib/python3.8/site-packages/airflow/decorators/base.py", line 241, in execute
    return_value = super().execute(context)
  File "/home/airflow/.local/lib/python3.8/site-packages/airflow/operators/python.py", line 199, in execute
    return_value = self.execute_callable()
  File "/home/airflow/.local/lib/python3.8/site-packages/airflow/operators/python.py", line 216, in execute_callable
    return self.python_callable(*self.op_args, **self.op_kwargs)
  File "/opt/airflow/dags/dag1_kafka_processing.py", line 70, in consume_from_kafka_source
    consumer = get_kafka_consumer('source')
  File "/opt/airflow/dags/dag1_kafka_processing.py", line 42, in get_kafka_consumer
    return KafkaConsumer(
  File "/home/airflow/.local/lib/python3.8/site-packages/kafka/consumer/group.py", line 387, in __init__
    self._client = self.config['kafka_client'](metrics=self._metrics, **self.config)
  File "/home/airflow/.local/lib/python3.8/site-packages/kafka/client_async.py", line 262, in __init__
    self.config['api_version'] = self.check_version()
  File "/home/airflow/.local/lib/python3.8/site-packages/kafka/client_async.py", line 1074, in check_version
    raise Errors.NoBrokersAvailable()
kafka.errors.NoBrokersAvailable: NoBrokersAvailable
[2025-10-28T23:26:05.215+0000] {taskinstance.py:1138} INFO - Marking task as FAILED. dag_id=dag1_calcul_trajet_kafka, task_id=ConsumKafka, execution_date=20251028T232500, start_date=20251028T232600, end_date=20251028T232605
[2025-10-28T23:26:05.231+0000] {standard_task_runner.py:107} ERROR - Failed to execute job 62 for task ConsumKafka (NoBrokersAvailable; 269)
[2025-10-28T23:26:05.269+0000] {local_task_job_runner.py:234} INFO - Task exited with return code 1
[2025-10-28T23:26:05.302+0000] {taskinstance.py:3280} INFO - 0 downstream tasks scheduled from follow-on schedule check
