[2025-10-29T20:38:05.344+0000] {taskinstance.py:1956} INFO - Dependencies all met for dep_context=non-requeueable deps ti=<TaskInstance: dag2_kafka_elastic_gcs.PutGCP scheduled__2025-10-29T20:37:00+00:00 [queued]>
[2025-10-29T20:38:05.353+0000] {taskinstance.py:1956} INFO - Dependencies all met for dep_context=requeueable deps ti=<TaskInstance: dag2_kafka_elastic_gcs.PutGCP scheduled__2025-10-29T20:37:00+00:00 [queued]>
[2025-10-29T20:38:05.354+0000] {taskinstance.py:2170} INFO - Starting attempt 1 of 1
[2025-10-29T20:38:05.370+0000] {taskinstance.py:2191} INFO - Executing <Task(_PythonDecoratedOperator): PutGCP> on 2025-10-29 20:37:00+00:00
[2025-10-29T20:38:05.382+0000] {standard_task_runner.py:60} INFO - Started process 3519 to run task
[2025-10-29T20:38:05.388+0000] {standard_task_runner.py:87} INFO - Running: ['***', 'tasks', 'run', 'dag2_kafka_elastic_gcs', 'PutGCP', 'scheduled__2025-10-29T20:37:00+00:00', '--job-id', '1517', '--raw', '--subdir', 'DAGS_FOLDER/dag2_elastic_gcs_ingestion.py', '--cfg-path', '/tmp/tmp_czxbhej']
[2025-10-29T20:38:05.392+0000] {standard_task_runner.py:88} INFO - Job 1517: Subtask PutGCP
[2025-10-29T20:38:05.466+0000] {task_command.py:423} INFO - Running <TaskInstance: dag2_kafka_elastic_gcs.PutGCP scheduled__2025-10-29T20:37:00+00:00 [running]> on host 46f6cfd4d166
[2025-10-29T20:38:05.588+0000] {taskinstance.py:2480} INFO - Exporting env vars: AIRFLOW_CTX_DAG_OWNER='***' AIRFLOW_CTX_DAG_ID='dag2_kafka_elastic_gcs' AIRFLOW_CTX_TASK_ID='PutGCP' AIRFLOW_CTX_EXECUTION_DATE='2025-10-29T20:37:00+00:00' AIRFLOW_CTX_TRY_NUMBER='1' AIRFLOW_CTX_DAG_RUN_ID='scheduled__2025-10-29T20:37:00+00:00'
[2025-10-29T20:38:05.602+0000] {connection.py:234} WARNING - Connection schemes (type: google_cloud_platform) shall not contain '_' according to RFC3986.
[2025-10-29T20:38:05.606+0000] {base.py:83} INFO - Using connection ID 'google_cloud_default' for task execution.
[2025-10-29T20:38:05.607+0000] {credentials_provider.py:353} INFO - Getting connection using `google.auth.default()` since no explicit credentials are provided.
[2025-10-29T20:38:05.608+0000] {taskinstance.py:2698} ERROR - Task failed with exception
Traceback (most recent call last):
  File "/home/airflow/.local/lib/python3.8/site-packages/airflow/models/taskinstance.py", line 433, in _execute_task
    result = execute_callable(context=context, **execute_callable_kwargs)
  File "/home/airflow/.local/lib/python3.8/site-packages/airflow/decorators/base.py", line 241, in execute
    return_value = super().execute(context)
  File "/home/airflow/.local/lib/python3.8/site-packages/airflow/operators/python.py", line 199, in execute
    return_value = self.execute_callable()
  File "/home/airflow/.local/lib/python3.8/site-packages/airflow/operators/python.py", line 216, in execute_callable
    return self.python_callable(*self.op_args, **self.op_kwargs)
  File "/opt/airflow/dags/dag2_elastic_gcs_ingestion.py", line 152, in put_gcs
    gcs_hook.upload(bucket_name=GCS_BUCKET, object_name=file_name, data=json_data)
  File "/home/airflow/.local/lib/python3.8/site-packages/airflow/providers/google/cloud/hooks/gcs.py", line 523, in upload
    client = self.get_conn()
  File "/home/airflow/.local/lib/python3.8/site-packages/airflow/providers/google/cloud/hooks/gcs.py", line 166, in get_conn
    credentials=self.get_credentials(), client_info=CLIENT_INFO, project=self.project_id
  File "/home/airflow/.local/lib/python3.8/site-packages/airflow/providers/google/common/hooks/base_google.py", line 298, in get_credentials
    credentials, _ = self.get_credentials_and_project_id()
  File "/home/airflow/.local/lib/python3.8/site-packages/airflow/providers/google/common/hooks/base_google.py", line 275, in get_credentials_and_project_id
    credentials, project_id = get_credentials_and_project_id(
  File "/home/airflow/.local/lib/python3.8/site-packages/airflow/providers/google/cloud/utils/credentials_provider.py", line 362, in get_credentials_and_project_id
    return _CredentialProvider(*args, **kwargs).get_credentials_and_project()
  File "/home/airflow/.local/lib/python3.8/site-packages/airflow/providers/google/cloud/utils/credentials_provider.py", line 243, in get_credentials_and_project
    credentials, project_id = self._get_credentials_using_adc()
  File "/home/airflow/.local/lib/python3.8/site-packages/airflow/providers/google/cloud/utils/credentials_provider.py", line 348, in _get_credentials_using_adc
    credentials, project_id = google.auth.default(scopes=self.scopes)
  File "/home/airflow/.local/lib/python3.8/site-packages/google/auth/_default.py", line 657, in default
    credentials, project_id = checker()
  File "/home/airflow/.local/lib/python3.8/site-packages/google/auth/_default.py", line 650, in <lambda>
    lambda: _get_explicit_environ_credentials(quota_project_id=quota_project_id),
  File "/home/airflow/.local/lib/python3.8/site-packages/google/auth/_default.py", line 270, in _get_explicit_environ_credentials
    credentials, project_id = load_credentials_from_file(
  File "/home/airflow/.local/lib/python3.8/site-packages/google/auth/_default.py", line 114, in load_credentials_from_file
    raise exceptions.DefaultCredentialsError(
google.auth.exceptions.DefaultCredentialsError: File /opt/***/laye-sda-5a8d14a4a3af.json was not found.
[2025-10-29T20:38:05.625+0000] {taskinstance.py:1138} INFO - Marking task as FAILED. dag_id=dag2_kafka_elastic_gcs, task_id=PutGCP, execution_date=20251029T203700, start_date=20251029T203805, end_date=20251029T203805
[2025-10-29T20:38:05.640+0000] {standard_task_runner.py:107} ERROR - Failed to execute job 1517 for task PutGCP (File /opt/***/laye-sda-5a8d14a4a3af.json was not found.; 3519)
[2025-10-29T20:38:05.682+0000] {local_task_job_runner.py:234} INFO - Task exited with return code 1
[2025-10-29T20:38:05.709+0000] {taskinstance.py:3280} INFO - 0 downstream tasks scheduled from follow-on schedule check
